Workbook

Sheet Read Me
A1: Nationwide Paid Petition Campaign Database
A3: Last verified | B3: October 24, 2026 (10 days before the Nov 3, 2026 general election)
A4: What this is | B4: Every petition project our research could find in all 50 states + DC, with status, deadlines, pay, firms and sources.
A5: Big picture | B5: Most 2026 ballot drives are finished. Live money is in the next wave: Massachusetts 2028 (first round due Nov 18 / Dec 2, 2026), Maine and Washington petitions to their legislatures, California's Jan 11, 2027 deadline, and the 2027 local / 2028 statewide cycle.
A7: STATUS KEY
A8: Confirmed active paid | B8: A current source (job ad naming the petition, finance filing, or official) shows paid circulators working it now.
A9: Strong evidence active paid | B9: Recent, credible reports of paid circulation, but not a current posting or filing.
A10: Active – paid unconfirmed | B10: The petition is collecting now, but we could not prove circulators are paid.
A11: Upcoming | B11: Announced or filed; collection hasn't started, or starts soon.
A12: Completed/Expired | B12: Drive is over. Kept because it shows who spends money and which firms they hire.
A13: No verified project | B13: We searched and found nothing verifiable. This means 'not found yet', NOT 'none exist'.
A15: TABS
A16: Database | B16: Every record. Use the filter arrows in the header row to sort by state, status, deadline, firm.
A17: Active Opportunities | B17: Live or near-live projects ranked by 5 scores (hiring, pay, deadline urgency, scale, evidence). Total = formula.
A18: State Coverage | B18: One row per state with live counts (formulas) so you can see where activity is and where gaps remain.
A19: Firms | B19: Circulation companies found, their states, contacts and pay.
A20: Job Postings | B20: Recent circulator job ads with stated pay.
A21: Trends & Laws | B21: Industry notes: pay rates, new laws, where the market is moving.
A22: New Discoveries | B22: Monitoring log. Add each newly found project here first, then move it to Database once verified.
A24: RULES WE FOLLOWED | B24: Nothing invented. 'unknown' means no reliable public source. A registered petition is NOT counted as paid. Contacts are official public business contacts only.
A25: Known gaps | B25: Several state election sites and campaign-finance systems blocked automated access (e.g. Florida initiative database, Nevada SOS, Missouri SOS 2028 page, Arizona filings). Those are the first places to check by hand.
A30: Today (edit to refresh 'Days Left') | B30: 46319

Sheet Database
A1: ID | B1: State | C1: Region | D1: Area | E1: Campaign / Petition | F1: Purpose | G1: Type | H1: Sponsor / Committee | I1: Circulation Firm | J1: Status | K1: Signatures Required | L1: Deadline | M1: Deadline (date) | N1: Days Left | O1: Signatures Collected | P1: Circulator Pay | Q1: Hiring Link | R1: Budget / Spend | S1: Decision Maker | T1: Public Contact | U1: Website | V1: Evidence Note | W1: Source 1 | X1: Source 2 | Y1: Source 3 | Z1: More Sources | AA1: Discovery Batch | AB1: Last Verified
A2: P001 | B2: Alabama | C2: Southeast | D2: Statewide | E2: Local recall/referendum/charter petitions | F2: Party/independent ballot access (Alabama has no statewide citizen initiative) | G2: Candidate/party ballot access | H2: unknown | I2: unknown | J2: No verified project | K2: 42,459 for party or statewide independent (2026) | L2: May 19, 2026 (statewide). The U.S. House deadline moved to Aug 11, 2026 for CD 1, 2, 6 and 7 (passed). | M2: 46161 | N2: =IF(M2="","",M2-'Read Me'!$B$30) -> -158 | O2: unknown | P2: unknown | Q2: unknown | R2: unknown | S2: unknown | T2: unknown | U2: unknown | V2: Checked Ballot Access News June 2026 only. Singleton v. Allen (May 26) struck the new districts. No verified paid petition activity. The search budget ran out before local petitions and job boards could be checked. | W2: https://ballot-access.org/2026/06/22/june-2026-ballot-access-news-print-edition/ | AA2: Pass 1 + Pass 2 | AB2: 46319
A3: P002 | B3: Alaska | C3: West | D3: Statewide | E3: Proposed initiative requiring state/federal candidates to gather signatures before running | F3: Require candidates for state and federal office in Alaska to gather petition signatures to get on the ballot | G3: Statutory initiative (application stage; likely 2028 target) | H3: unknown | I3: unknown | J3: Upcoming | K3: unknown | L3: unknown | N3: =IF(M3="","",M3-'Read Me'!$B$30) | O3: unknown | P3: unknown | Q3: unknown | R3: unknown | S3: unknown | T3: unknown | U3: unknown | V3: Known only from the ADN headline (10/14/26); the article could not be fetched because robots.txt blocks it. Sponsors and status unverified. | W3: https://www.adn.com/politics/2026/10/14/proposed-ballot-initiative-would-require-alaska-federal-state-candidates-to-gather-signatures-before-running-for-office/ | AA3: Pass 1 | AB3: 46319
A4: P003 | B4: Alaska | C4: West | D4: Statewide | E4: 25ANMA - Alaska Natural Medicine Act | F4: Regulated natural medicine (psychedelics) program; decriminalize personal use for adults 21+ | G4: Statutory initiative | H4: Natural Alaska Medicine Inc. (nonprofit) | I4: unknown | J4: Completed/Expired | K4: 10% of voters in last general election, from at least 30 of 40 House districts (exact number unknown) | L4: Booklet filing deadline 2026-09-14 (passed) | M4: 46279 | N4: =IF(M4="","",M4-'Read Me'!$B$30) -> -40 | O4: unknown | P4: unknown | Q4: unknown | R4: unknown | S4: unknown | T4: unknown | U4: https://www.elections.alaska.gov/petitions-and-ballot-measures/petition-status/petition_id/gr8j9 | V4: Circulation window ended 9/14/26. Whether booklets were filed or signatures are under review is unknown. | W4: https://www.elections.alaska.gov/petitions-and-ballot-measures/ | X4: https://alaskabeacon.com/briefs/ballot-initiative-to-decriminalize-psychedelics-in-alaska-cleared-for-signature-gathering/ | AA4: Pass 1 | AB4: 46319
A5: P004 | B5: Alaska | C5: West | D5: Statewide | E5: 25USCV - Only U.S. citizens may be qualified voters | F5: Amend AS 15.05.010 to state explicitly that only U.S. citizens meeting listed requirements may vote | G5: Statutory initiative | H5: unknown | I5: unknown | J5: Completed/Expired | K5: 34,098 across 30 House districts | L5: Properly filed 2026-03-17; Nov 3, 2026 ballot unless legislature acts | M5: 46098 | N5: =IF(M5="","",M5-'Read Me'!$B$30) -> -221 | O5: 34,944 qualified across 40 House districts | P5: unknown | Q5: unknown | R5: unknown | S5: unknown | T5: unknown | U5: https://www.elections.alaska.gov/petitions-and-ballot-measures/ | V5: Certified 3/17/26. The AK petitions page still lists it as 'booklets circulating' with a 10/29/26 booklet deadline, which conflicts with the certification release and looks stale. | W5: https://www.elections.alaska.gov/lieutenant-governor-nancy-dahlstrom-certifies-proper-filing-of-ballot-initiative-petition-25uscv/ | X5: https://www.elections.alaska.gov/petitions-and-ballot-measures/ | AA5: Pass 1 | AB5: 46319
A6: P005 | B6: Arizona | C6: Mountain/Southwest | D6: City of Scottsdale | E6: Axon headquarters / apartments zoning referendum | F6: Refer the city council's November 2024 approval of Axon's HQ campus and apartments to voters | G6: Municipal referendum | H6: Taxpayers Against Awful Apartment Zoning Exemptions (TAAAZE); signature drive described as union-linked | I6: unknown | J6: Completed/Expired | K6: unknown (city clerk certified it met the constitutional minimum) | L6: Filed December 2024; certified January 30, 2025 | M6: 45687 | N6: =IF(M6="","",M6-'Read Me'!$B$30) -> -632 | O6: More than 26,000 | P6: unknown | Q6: unknown | R6: unknown | S6: unknown | T6: unknown | U6: https://www.scottsdaleaz.gov/elections/referendum | V6: Shows local referendum demand in Arizona. A state bill was moving to cancel the vote; whether it reached the November 2026 ballot was not verified. | W6: https://www.abc15.com/news/business/axon-headquarters-referendum-certified-by-city-of-scottsdale | X6: https://www.yahoo.com/news/collecting-26-000-signatures-scottsdale-195209122.html | AA6: Pass 1 | AB6: 46319
A7: P006 | B7: Arizona | C7: Mountain/Southwest | D7: Statewide | E7: Protect the Vote Arizona (constitutional right to early and mail-in voting) | F7: Put early and mail voting into the Arizona Constitution | G7: Statewide constitutional amendment initiative | H7: Protect the Vote Arizona (funded largely by United Food and Commercial Workers and other unions, per KJZZ) | I7: unknown (Lumen Strategies managed the campaign; Lumen is a PR/consulting firm, not confirmed as the signature vendor) | J7: Completed/Expired | K7: 383,923 valid | L7: July 2, 2026 (campaign chose not to file) | M7: 46205 | N7: =IF(M7="","",M7-'Read Me'!$B$30) -> -114 | O7: About 439,000 gathered, not submitted | P7: unknown | Q7: unknown | R7: unknown | S7: Stacy Pearson (spokesperson; Lumen Strategies co-founder) | T7: unknown | U7: unknown | V7: Dropped because the expected validity rate was too low. Arizona Agenda said the drive was 'largely undertaken by volunteers' (about 1,700 circulators). It is a possible 2028 refile, but no source mentions 2028 plans. | W7: https://www.kjzz.org/elections/2026-07-02/arizona-group-drops-petition-to-enshrine-early-voting-in-the-state-constitution | X7: https://www.arizonaagenda.com/p/protect-the-vote-s-final-push | AA7: Pass 1 | AB7: 46319
A8: P007 | B8: Arizona | C8: Mountain/Southwest | D8: Statewide | E8: Protect Education, Accountability Now (ESA limits) | F8: Limit Empowerment Scholarship Account eligibility to families earning under $150,000 (starting 2027-28) and bar luxury purchases and paying family members | G8: Statewide initiated statute | H8: Protect Education, Accountability Now campaign (endorsed by Arizona Education Association and Save Our Schools Arizona) | I8: unknown | J8: Completed/Expired | K8: 255,949 valid | L8: July 2, 2026 (submitted) | M8: 46205 | N8: =IF(M8="","",M8-'Read Me'!$B$30) -> -114 | O8: 421,451 submitted | P8: unknown | Q8: unknown | R8: unknown | S8: unknown | T8: unknown | U8: unknown | V8: Only one of six 2026 Arizona initiatives filed signatures. No firm named in the source. A 400K+ drive in Arizona almost always uses paid circulators, but no source here confirms it. Check the AZ SOS paid-circulator registry or SeeTheMoney to see who was paid. | W8: https://news.ballotpedia.org/2026/07/07/arizona-campaign-submits-421451-signatures-for-initiative-to-limit-empowerment-scholarship-account-eligibility-and-spending/ | AA8: Pass 1 + Pass 2 | AB8: 46319
A9: P008 | B9: Arizona | C9: South | D9: Benson (Cochise County) | E9: Benson recall - Mayor Joe Konrad and 4 council members | F9: Recall city officials | G9: Municipal recall | H9: Committee for a Better Benson | I9: unknown | J9: Completed/Expired | K9: Konrad 327; Johnson 301; Boyle, Hayes, Maldonado 267 each | L9: Petitions submitted Oct 29 2025 | M9: 45959 | N9: =IF(M9="","",M9-'Read Me'!$B$30) -> -360 | O9: unknown | P9: unknown | Q9: unknown | R9: unknown | S9: unknown | T9: unknown | U9: unknown | V9: Follow-up headline indicates the Konrad recall 'fell short for common petition issues' (article body not fetched). No active AZ recall verified. | W9: https://www.myheraldreview.com/news/benson/recall-effort-could-oust-benson-mayor-and-4-of-6-council-members/article_c4e47701-9375-4059-90af-f546cb7905ba.amp.html | X9: https://www.myheraldreview.com/news/benson/konrad-recall-effort-fell-short-for-common-petition-issues/article_b2a9d91b-bf7d-4406-98cc-26ee613abe78.amp.html | AA9: Pass 2 (gap-fill) | AB9: 46319
A10: P009 | B10: Arizona | C10: South | D10: Phoenix | E10: Right-Size Consulting paid petition canvassing program | F10: Petition signature collection (campaign not named) | G10: unknown | H10: unknown | I10: Right-Size Consulting | J10: Completed/Expired | K10: unknown | L10: unknown | N10: =IF(M10="","",M10-'Read Me'!$B$30) | O10: unknown | P10: $20/hour | Q10: https://careers.arena.run/companies/job-post-2/jobs/68651818-right-size-consulting-canvasser | R10: unknown | S10: unknown | T10: email listed on posting (obfuscated in fetch) | U10: unknown | V10: Posted Feb 25 2026, before the July 2 2026 AZ filing deadline; likely tied to 2026 cycle. Current status unknown. | W10: https://careers.arena.run/companies/job-post-2/jobs/68651818-right-size-consulting-canvasser | AA10: Pass 2 (gap-fill) | AB10: 46319
A11: P010 | B11: Arkansas | C11: Plains/Texas | D11: Statewide | E11: Protect AR Rights – Ballot Measure Rights Amendment | F11: Constitutional amendment protecting the right to initiative/referendum; bar the legislature from amending or repealing citizen amendments | G11: Statewide constitutional initiative, 2026 | H11: Protect AR Rights (ballot question committee; member org Arkansas Public Policy Panel, Exec. Dir. Bill Kopsky) | I11: unknown | J11: Completed/Expired | K11: 90,704 verified | L11: July 3, 2026 (submitted) | M11: 46206 | N11: =IF(M11="","",M11-'Read Me'!$B$30) -> -113 | O11: 108,837 submitted | P11: unknown | Q11: unknown | R11: unknown | S11: Bill Kopsky (Arkansas Public Policy Panel) | T11: unknown | U11: unknown | V11: The AR SOS page lists 'None' citizen-initiated measures for the 2026 general election, so this measure apparently did not qualify (reason not found). A federal judgment (WD Ark., Aug 21, 2026) struck down some Arkansas initiative restrictions. No 2028 AG-certified ballot titles were found, and the paid canvasser registration list was not checked. | W11: https://news.ballotpedia.org/2026/07/08/signatures-submitted-for-arkansas-initiative-to-prohibit-the-state-legislature-from-amending-or-repealing-constitutional-amendments-and-require-voter-approval-for-changes-to-the-initiative-and-referen/ | X11: https://arkansasadvocate.com/2025/07/28/arkansas-attorney-general-approves-second-direct-democracy-ballot-title/ | Y11: https://www.sos.arkansas.gov/elections/initiatives-and-referenda | AA11: Pass 1 | AB11: 46319
A12: P011 | B12: California | C12: West | D12: Statewide | E12: Repeal Top-Two Open Primary (SOS #2022 / AG 26-0004) | F12: Repeal California's top-two open primary system adopted by voters in 2010 | G12: Initiative constitutional amendment (Nov 7, 2028 ballot) | H12: Proponent: Steven Maviglio (Democratic consultant). Supporters named by proponent include California Labor Federation, Greens, Carl DeMaio, a former Republican Party chair | I12: unknown | J12: Active – paid unconfirmed | K12: 874,641 valid | L12: 2027-01-11 (end of 180-day circulation period; submit to county elections officials) | M12: 46398 | N12: =IF(M12="","",M12-'Read Me'!$B$30) -> 79 | O12: unknown (CA SOS 25%-signature list showed 'None at this time' when checked) | P12: unknown | Q12: unknown | R12: unknown (no committee appeared on FPPC pending/circulating top-contributor lists checked) | S12: Steven Maviglio (proponent of record) | T12: Proponent email published by CA SOS: steven.maviglio@gmail.com | U12: undothetoptwo.com | V12: Only CA statewide initiative still in circulation (cleared 7/14/26, deadline 1/11/27). Needing ~875k valid signatures in 180 days normally implies paid circulation, but no source found confirming a firm, pay rate or committee spending. Check Cal-Access for the committee's payments to petition firms. No 25% report filed as of check. | W12: https://www.sos.ca.gov/administration/news-releases-and-advisories/2026-news-releases-and-advisories/proposed-initiative-enters-circulation-repeals-top-two-open-primary-election-process-initiative-constitutional-amendment | X12: https://www.kpbs.org/news/politics/2026/07/16/effort-to-repeal-californias-top-two-jungle-primary-system-is-closer-to-qualifying-for-the-2028-ballot | Y12: https://ivn.us/more-choice-california-launches-to-defend-nonpartisan-primary-as-democratic-and-republican-operatives-quietly-join-forces-to-repeal-it-2026-05-13/ | Z12: https://fox5sandiego.com/news/no-more-jungle-primary-a-new-initiative-would-end-californias-top-two-system/amp/; https://www.fppc.ca.gov/transparency/top-contributors/nov-26-gen/pending-circulating-ballot-measures.html; https://sos.ca.gov/elections/ballot-measures/initiative-and-referendum-status/initiatives-referenda-cleared-circulation; https://sos.ca.gov/elections/ballot-measures/initiative-and-referendum-status/circulating-initiatives-25percent-signatures; https://ballot-access.org/?p=93674 | AA12: Pass 1 + Pass 2 | AB12: 46319
A13: P012 | B13: California | C13: West | D13: Statewide | E13: Exempts Additional Food Products from State and Local Sales Taxes (SOS #2023 / AG 26-0005) | F13: Constitutional amendment expanding sales-tax exemption for food products | G13: Initiative constitutional amendment | H13: John Pimentel (proponent) | I13: unknown | J13: Active – paid unconfirmed | K13: 874,641 valid | L13: 2027-03-24 | M13: 46470 | N13: =IF(M13="","",M13-'Read Me'!$B$30) -> 151 | O13: unknown | P13: unknown | Q13: unknown | R13: unknown | S13: John Pimentel | T13: John Pimentel, 20 Park Road, Burlingame, CA 94010; (650) 269-8933; John@JohnPimentel.com (per CA SOS release PR26-122) | U13: unknown | V13: Entered circulation Sept 25, 2026. It is the newest CA statewide initiative in circulation, per the SOS 2026 release index. No funding committee, firm or signature drive activity was found. A proponent with no visible funding is a possible client for a feasibility or full-campaign pitch. | W13: https://www.sos.ca.gov/administration/news-releases-and-advisories/2026-news-releases-and-advisories/california-secretary-state-shirley-n-weber-phd-announces-proposed-initiative-has-entered-circulation-exempts-additional-food-pro | X13: https://www.sos.ca.gov/administration/news-releases-and-advisories/2026-news-releases-and-advisories | AA13: Pass 2 (gap-fill) | AB13: 46319
A14: P013 | B14: California | C14: West | D14: Los Angeles and surrounding areas | E14: Urban Signers LLC - Signature Collector (unnamed petition projects) | F14: Paid signature collection for unnamed 'official petition and local campaign projects' | G14: unknown (local/official petitions, unspecified) | H14: unknown | I14: Urban Signers LLC | J14: Active – paid unconfirmed | K14: unknown | L14: unknown | N14: =IF(M14="","",M14-'Read Me'!$B$30) | O14: unknown | P14: $5 or $10 per signature depending on project; advertised $200-$1,000/day; paid weekly or bi-weekly | Q14: https://urban-signers-llc.careerplug.com/jobs/3365854 | R14: unknown | S14: unknown | T14: Apply via CareerPlug form only; no phone/email listed | U14: https://urban-signers-llc.careerplug.com/jobs/3365854 | V14: Paid job ad; page metadata updated 2026-10-16 (original post date unknown). Names no specific petition, and the only statewide CA petition circulating is the top-two repeal, so which projects are active is unverified. | W14: https://urban-signers-llc.careerplug.com/jobs/3365854 | AA14: Pass 1 | AB14: 46319
A15: P014 | B15: California | C15: West | D15: Statewide | E15: Prohibit use after 2026 of Prop 50 temporary congressional maps (AG 25-0031) | F15: Constitutional amendment ending the 2025 voter-adopted temporary congressional maps after 2026 | G15: Initiative constitutional amendment | H15: James V. Lacy (proponent) | I15: unknown | J15: Completed/Expired | K15: 874,641 valid | L15: 2026-07-13 | M15: 46216 | N15: =IF(M15="","",M15-'Read Me'!$B$30) -> -103 | O15: unknown | P15: unknown | Q15: unknown | R15: unknown | S15: James V. Lacy | T15: c/o Bradley W. Hertz, Esq., 22815 Ventura Blvd #405, Los Angeles, CA 91364; (818) 593-2949; brad@bradleyhertzlaw.com (per CA SOS release PR26-08) | U15: unknown | V15: The circulation window has closed and the outcome was not verified. | W15: https://www.sos.ca.gov/administration/news-releases-and-advisories/2026-news-releases-and-advisories/proposed-initiative-enters-circulation-prohibits-use-after-2026-temporary-congressional-district-maps-adopted-voters-2025-respon | AA15: Pass 2 (gap-fill) | AB15: 46319
A16: P015 | B16: California | C16: West | D16: Statewide | E16: Exempts Homeowners 60+ from Property Taxes (AG 25-0035) | F16: Constitutional amendment exempting certain homeowners aged 60+ from property taxes | G16: Initiative constitutional amendment | H16: Rishi Kumar (proponent) | I16: unknown | J16: Completed/Expired | K16: 874,641 valid | L16: 2026-08-04 | M16: 46238 | N16: =IF(M16="","",M16-'Read Me'!$B$30) -> -81 | O16: unknown | P16: unknown | Q16: unknown | R16: unknown | S16: Rishi Kumar | T16: P.O. Box 110484, Campbell, CA 95011; (408) 805-5993; VoteRishiKumar@gmail.com (per CA SOS release PR26-21) | U16: unknown | V16: The circulation window has closed. Whether signatures were submitted is unknown. The proponent could refile for 2028. | W16: https://www.sos.ca.gov/administration/news-releases-and-advisories/2026-news-releases-and-advisories/proposed-initiative-enters-circulation-exempts-certain-homeowners-aged-60-or-older-property-taxes-initiative-constitutional-amen | AA16: Pass 2 (gap-fill) | AB16: 46319
A17: P016 | B17: California | C17: West | D17: Statewide | E17: Changes Ballot Initiative Procedures and Elections (AG 26-0001/26-0002; SOS #2019/#2020) | F17: Change ballot initiative procedures and elections (constitutional amendment and statute) | G17: Initiative constitutional amendment and statute | H17: Thomas Jefferson Cares (proponent) | I17: unknown | J17: Completed/Expired | K17: 874,641 valid | L17: 2026-10-05 (passed) | M17: 46300 | N17: =IF(M17="","",M17-'Read Me'!$B$30) -> -19 | O17: unknown (no 25% report on SOS list) | P17: unknown | Q17: unknown | R17: unknown | S17: Thomas Jefferson Cares (proponent) | T17: 12816 Inglewood Ave #383, Hawthorne, CA 90250; (310) 929-0260; Tom@UH.do (as published by CA SOS) | U17: unknown | V17: Circulation deadline passed 10/5/26. No evidence of paid circulation or a 25% signature report, so it almost certainly did not qualify. | W17: https://www.sos.ca.gov/administration/news-releases-and-advisories/2026-news-releases-and-advisories/california-secretary-state-shirley-n-weber-phd-announces-proposed-initiative-has-entered-circulation-changes-ballot-initiative-p | X17: https://sos.ca.gov/elections/ballot-measures/initiative-and-referendum-status/initiatives-referenda-cleared-circulation | AA17: Pass 1 | AB17: 46319
A18: P017 | B18: California | C18: West | D18: Statewide | E18: Changes Ballot Initiative Procedures (AG 26-0001) and California Strategic Implementation Board (AG 26-0003) | F18: Create a California Strategic Implementation Board to change numerous aspects of state law and government | G18: Initiative constitutional amendment | H18: Thomas Jefferson Cares (proponent) | I18: unknown | J18: Completed/Expired | K18: 874,641 valid | L18: 2026-10-13 (passed) | M18: 46308 | N18: =IF(M18="","",M18-'Read Me'!$B$30) -> -11 | O18: unknown (no 25% report on SOS list) | P18: unknown | Q18: unknown | R18: unknown | S18: Thomas Jefferson Cares (proponent) | T18: (310) 929-0260; Tom@UH.do (proponent contact CA SOS published for this proponent's related measure) | U18: unknown | V18: Circulation deadline passed 10/13/26; no signs of a paid drive. The SOS cleared-for-circulation list also shows a fourth entry with this same title under Steven Maviglio (SOS #2022, deadline 1/11/27), but the SOS press release for #2022 gives the top-two repeal title. Likely a listing error; the top-two record above relies on the press release. | W18: https://www.sos.ca.gov/administration/news-releases-and-advisories/2026-news-releases-and-advisories/california-secretary-state-shirley-n-weber-phd-announces-proposed-initiative-has-entered-circulation-changes-ballot-initiative-p | X18: https://www.sos.ca.gov/administration/news-releases-and-advisories/2026-news-releases-and-advisories/california-secretary-state-shirley-n-weber-phd-announces-proposed-initiative-has-entered-circulation | Y18: https://sos.ca.gov/elections/ballot-measures/initiative-and-referendum-status/initiatives-referenda-cleared-circulation | AA18: Pass 1 + Pass 2 | AB18: 46319
A19: P018 | B19: California | C19: West | D19: Statewide | E19: CA per-signature pay benchmark - Billionaire Tax and counter-measure (2026 cycle) | F19: Market pay-rate evidence for CA paid circulators | G19: Initiative (statewide) | H19: Billionaire Tax Act supporters; the counter-measure was backed by Sergey Brin among others | I19: unknown (data cited from consulting firm Bicker, Castillo, Fairbanks & Spitz) | J19: Completed/Expired | K19: unknown | L19: Completed (2026 cycle) | N19: =IF(M19="","",M19-'Read Me'!$B$30) | O19: unknown | P19: $12 per signature (billionaire tax, up from $4 in fall 2025); $15 per signature (counter-measure), as of late Feb 2026 | Q19: unknown | R19: unknown | S19: unknown | T19: unknown | U19: unknown | V19: This is pay-rate context, not an open job. No current (Oct 2026) CA circulator job ad with a stated pay rate was verified: a Craigslist WA ad and a JobsInGovernment Carter Consulting ad could not be retrieved. | W19: https://sfstandard.com/2026/03/05/california-ballot-bounties-have-gone-wild/ | AA19: Pass 2 (gap-fill) | AB19: 46319
A20: P019 | B20: California | C20: West | D20: Los Angeles (Van Nuys, Koreatown, NE LA, South LA) | E20: The Outreach Team - LA petitioners (corporate accountability initiative + LA Fire Department expansion initiative) | F20: Signature gathering for two LA ballot initiatives: hold large corporations accountable/reinvest in communities; expand the LA Fire Department | G20: Local (City of Los Angeles) ballot initiatives | H20: unknown | I20: The Outreach Team | J20: Completed/Expired | K20: unknown | L20: Job posting closed 2026-05-19 | M20: 46161 | N20: =IF(M20="","",M20-'Read Me'!$B$30) -> -158 | O20: unknown | P20: $27/hr base, $28/hr leads, $20-$150 daily bonuses, +$2/hr bilingual, overtime, referral bonuses | Q20: https://www.theoutreachteam.net/interest-form-tot | R20: unknown | S20: unknown | T20: https://www.theoutreachteam.net/interest-form-tot | U20: https://www.theoutreachteam.net | V20: Confirmed paid hourly drive but expired (closed 5/19/26). Useful because The Outreach Team is an hourly-pay firm active in LA local measures. Measure outcomes not checked. | W20: https://la2050.org/job/the-outreach-team-petitioners-make-a-difference-dollars-27-dollars-28-hr-bonuses | AA20: Pass 1 | AB20: 46319
A21: P020 | B21: California | C21: West | D21: City of San Diego | E21: Balboa Park Free Parking Restoration Act / Trash fee repeal petitions | F21: Repeal Balboa Park paid parking and the city trash fee | G21: Municipal initiative (with council-rehear threshold) | H21: Richard Bailey (Balboa Park measure); San Diego United Communities (Margaret Virissimo) | I21: unknown | J21: Completed/Expired | K21: About 81,000-82,000 verified for the ballot; about 24,000-24,500 to force a council rehearing | L21: June 2026 (exact date unknown) | N21: =IF(M21="","",M21-'Read Me'!$B$30) | O21: unknown | P21: unknown | Q21: unknown | R21: unknown | S21: Richard Bailey; Margaret Virissimo | T21: unknown | U21: repealthefees.com | V21: Volunteer drives that targeted the Nov 2026 ballot. The deadlines have passed and outcomes were not verified. Fee disputes like these show local demand that could recur. | W21: https://timesofsandiego.com/politics/2026/04/05/petition-to-repeal-parking-fees-at-balboa-park-cleared-to-gather-signatures/ | X21: https://www.10news.com/news/local-news/san-diego-petition-drive-targets-trash-fee-balboa-park-parking-charges-on-mothers-day | AA21: Pass 2 (gap-fill) | AB21: 46319
A22: P021 | B22: California | C22: West | D22: Statewide | E22: UC support staff first-time homebuyer down payment loan program initiative | F22: Require UC to create a down payment loan program (20% of home value) for eligible UC support staff | G22: Initiative constitutional amendment (qualified for Nov 7, 2028 ballot) | H22: AFSCME Local 3299 | I22: unknown | J22: Completed/Expired | K22: 874,641 valid | L22: Qualified 2026-10-02; withdrawal deadline 2028-06-29 | M22: 46297 | N22: =IF(M22="","",M22-'Read Me'!$B$30) -> -22 | O22: 1,265,569 raw submitted; 947,631 valid (full count) | P22: unknown | Q22: unknown | R22: unknown | S22: AFSCME 3299 (sponsor) | T22: unknown | U22: unknown | V22: First initiative qualified for CA 2028 ballot. Drive is finished; useful as a sign that AFSCME 3299 runs large signature drives. Firm and spending not reported in source; check Cal-Access. | W22: https://news.ballotpedia.org/2026/10/06/first-initiative-qualifies-for-the-2028-ballot-in-california/ | AA22: Pass 1 | AB22: 46319
A23: P022 | B23: Colorado | C23: Mountain/Southwest | D23: Colorado Springs and Denver | E23: 2027 municipal elections - candidate nominating petitions (Colorado Springs Apr 6, 2027; Denver 2027 municipal) | F23: Candidate petitions for Colorado Springs Mayor and 3 At-Large Council seats, plus district seats; Denver 2027 municipal candidate petitions of nomination | G23: Candidate ballot access petition | H23: Individual candidates (not yet known) | I23: unknown | J23: Upcoming | K23: unknown | L23: Colorado Springs candidate filing Jan 4-25, 2027; Denver deadline per the 2027 candidate packet (not read in detail) | M23: 46391 | N23: =IF(M23="","",M23-'Read Me'!$B$30) -> 72 | O23: unknown | P23: unknown | Q23: unknown | R23: unknown | S23: Candidates (TBD) | T23: Colorado Springs City Clerk; Denver Clerk and Recorder Elections Division | U23: https://mayor.coloradosprings.gov/city-clerk/page/candidate-and-campaign-information | V23: This is a real upcoming petition window. Paid circulation is NOT confirmed; municipal candidate petitions are often volunteer-gathered. Also, Colorado's 2027-28 statewide title board list could not be read (the SOS 2027-2028 filings page was blocked), so statewide 2028 filings are unverified. Any paid entity must be licensed by the CO SOS and its circulators must wear 'PAID CIRCULATOR' badges. | W23: https://mayor.coloradosprings.gov/city-clerk/page/candidate-and-campaign-information | X23: https://www.denvergov.org/files/assets/public/v/1/clerk-and-recorder/documents/elections/guides/2027-municipal-candidate-information-packet-pdf-version.pdf | AA23: Pass 1 | AB23: 46319
A24: P023 | B24: Colorado | C24: Mountain/Southwest | D24: Statewide | E24: Protect Kids Colorado Initiatives #108, #109, #110 (now Propositions 133, 134, 135) | F24: #108 life sentence for child sex trafficking; #109 restrict transgender students in sports; #110 ban certain gender-affirming procedures for minors | G24: Statewide initiated statutes | H24: Protect Kids Colorado (Executive Director Erin Lee; founder Kevin Lundberg); Protect our Children Issue Committee for fundraising | I24: Taylor Petition Management (Tracy Taylor), registered with the state for #108-110 | J24: Completed/Expired | K24: 124,238 valid each | L24: #108 Feb 16, 2026; #109 and #110 Feb 20, 2026 (all submitted by Feb 20) | M24: 46069 | N24: =IF(M24="","",M24-'Read Me'!$B$30) -> -250 | O24: Group said more than 170,000 submitted for each | P24: unknown | Q24: unknown | R24: unknown | S24: Erin Lee (Executive Director); Michele Austin (proponent/strategist) | T24: unknown | U24: https://protectkidscolorado.org | V24: Confirmed paid by the end: the drive switched from volunteers to a licensed paid petition entity (Taylor Petition Management), and all three qualified as Props 133-135. Proves Taylor Petition Management is active in Colorado. | W24: https://coloradotimesrecorder.com/2026/02/activists-now-paying-for-signatures-for-anti-trans-ballot-measures/76656/ | X24: https://completecolorado.com/2025/09/05/ballot-measures-protecting-kids-signature-gathering/ | Y24: https://kiowacountypress.net/content/14-measures-will-appear-colorados-statewide-ballot-2026 | AA24: Pass 1 | AB24: 46319
A25: P024 | B25: Colorado | C25: Mountain/Southwest | D25: Statewide | E25: Initiative 177 - right to buy and use natural gas for cooking and heating | F25: Constitutional right to purchase and sell natural gas for homes and businesses | G25: Statewide constitutional initiative | H25: Advance Colorado; funders for signatures Colorado Dawn and A Common Sense America | I25: unknown | J25: Completed/Expired | K25: 124,238 valid | L25: Filed June 24, 2026; verification due by Aug 21, 2026 | M25: 46197 | N25: =IF(M25="","",M25-'Read Me'!$B$30) -> -122 | O25: unknown | P25: unknown | Q25: unknown | R25: Colorado Dawn $750,000 for signatures; A Common Sense America $625,000 to help collect signatures (per KUNC) | S25: unknown | T25: unknown | U25: unknown | V25: About $1.375M was earmarked for signatures, which is strong evidence of paid circulation. Advance Colorado is linked to 6 of the 13 citizen initiatives on the 2026 CO ballot (Amendments 81, 82, 85, 86 and Props 132, 136), making it the largest repeat buyer of petition work in the region. KUNC puts the cost at $1M-$3M per measure. Firm names are in the CO SOS paid-circulator reports and TRACER, which were not read. | W25: https://news.ballotpedia.org/2026/06/26/signatures-submitted-for-colorado-initiative-for-the-right-to-purchase-and-sell-natural-gas-for-cooking-and-heating-in-homes-or-businesses/ | X25: https://www.kunc.org/politics/2026-08-21/colorado-ballot-questions-meant-to-keep-special-interests-in-check-are-increasingly-created-by-them | AA25: Pass 1 | AB25: 46319
A26: P025 | B26: Colorado | C26: Mountain/Southwest | D26: City and County of Denver | E26: Denver force-feeding / foie gras ban initiated ordinance | F26: Ban force-feeding birds and the sale of force-fed products in Denver | G26: Municipal initiated ordinance | H26: Pro-Animal Colorado | I26: unknown | J26: Completed/Expired | K26: unknown | L26: Nov 3, 2026 ballot | M26: 46329 | N26: =IF(M26="","",M26-'Read Me'!$B$30) -> 10 | O26: unknown | P26: unknown | Q26: unknown | R26: unknown | S26: unknown | T26: unknown | U26: unknown | V26: The only citizen-initiated Denver measure for Nov 2026 per Brownstein. Whether circulators were paid or volunteers is unknown. | W26: https://www.bhfs.com/insight/denvers-2026-ballot-takes-shape-key-initiatives-and-the-at-large-city-council-vacancy-election/ | X26: https://www.denvergov.org/files/assets/public/v/1/clerk-and-recorder/documents/elections-division/2025/measures/force-feeding-sample-petition-stapled-copy-with-blue-manuscript.pdf | AA26: Pass 1 | AB26: 46319
A27: P026 | B27: Colorado | C27: Mountain/Southwest | D27: Denver metro and Colorado Springs | E27: Landslide Political - candidate signature gathering and canvassing (Colorado) | F27: Signature gathering to qualify 2026 candidates for the Colorado ballot, plus door-to-door canvassing | G27: Candidate ballot access petition / canvass | H27: Unnamed 2026 candidates | I27: Landslide Political | J27: Completed/Expired | K27: unknown | L27: unknown | N27: =IF(M27="","",M27-'Read Me'!$B$30) | O27: unknown | P27: $25/hour ($150 per 6-hour shift), paid weekly | Q27: https://landslidepolitical.recruitee.com/o/canvasser-hiring-immediately-denver-metro-area-25hr | R27: unknown | S27: unknown | T27: Apply via the Recruitee posting; no phone or email listed | U27: https://landslidepolitical.recruitee.com | V27: The posting is still live but undated and refers to 2026 ballot qualification, which is over. Landslide keeps standing postings, so it could re-staff for 2027 municipal or 2028 work. That is unconfirmed. | W27: https://landslidepolitical.recruitee.com/o/canvasser-hiring-immediately-denver-metro-area-25hr | X27: https://landslidepolitical.recruitee.com/o/canvasser-hiring-immediately-colorado-springs-25hr | AA27: Pass 1 | AB27: 46319
A28: P027 | B28: Colorado | C28: Mountain/Southwest | D28: Colorado Springs | E28: Killin for Colorado - candidate ballot-access petition | F28: Collect signatures to put a Democratic candidate on the 2026 ballot | G28: Candidate ballot access petition | H28: Killin for Colorado (candidate committee) | I28: 503 Strategies (recruiting contact domain) | J28: Completed/Expired | K28: unknown | L28: unknown (2026 candidate petition period is over) | N28: =IF(M28="","",M28-'Read Me'!$B$30) | O28: unknown | P28: $30/hour, 10-30 hrs/week | Q28: https://jobs.arena.run/jobs/paid-petition-circulator-reci-b-ea-nzesly5-h-kl/ | R28: unknown | S28: unknown | T28: annika@503-strategies.com (from job posting) | U28: unknown | V28: The job posting confirms a paid circulator role, but it is undated and tied to the 2026 ballot, so it has expired. It shows 503 Strategies does paid candidate petitioning in Colorado. | W28: https://jobs.arena.run/jobs/paid-petition-circulator-reci-b-ea-nzesly5-h-kl/ | X28: https://careers.arena.run/companies/job-post-2/jobs/64551809-killin-for-colorado-paid-petition-circulator | AA28: Pass 1 | AB28: 46319
A29: P028 | B29: Connecticut | C29: Northeast | D29: Statewide/local | E29: No verified project | F29: n/a | G29: n/a | H29: n/a | I29: n/a | J29: No verified project | K29: n/a | L29: n/a | N29: =IF(M29="","",M29-'Read Me'!$B$30) | O29: n/a | P29: n/a | Q29: n/a | R29: n/a | S29: n/a | T29: n/a | U29: n/a | V29: Not researched: search budget exhausted. CT has no statewide citizen initiative, so look at town referendum petitions on budgets and ordinances and at 2027 municipal candidate petitions. Needs a follow-up pass. | AA29: Pass 1 + Pass 2 | AB29: 46319
A30: P029 | B30: Delaware | C30: Northeast | D30: Statewide/local | E30: No verified project | F30: n/a | G30: n/a | H30: n/a | I30: n/a | J30: No verified project | K30: n/a | L30: n/a | N30: =IF(M30="","",M30-'Read Me'!$B$30) | O30: n/a | P30: n/a | Q30: n/a | R30: n/a | S30: n/a | T30: n/a | U30: n/a | V30: Not researched: search budget exhausted. Delaware has no statewide citizen initiative. Needs a follow-up pass on municipal petitions and minor-party ballot access. | AA30: Pass 1 + Pass 2 | AB30: 46319
A31: P030 | B31: District of Columbia | C31: Northeast | D31: Citywide | E31: Initiative 87: DC Living Wage for All ($25 minimum wage) | F31: Raise DC minimum wage to $25 by July 1, 2029 and phase out tipped subminimum by 2031 | G31: Initiative (DC citywide) | H31: One Fair Wage (president Saru Jayaraman); proposer Trupti Patel per 51st | I31: unknown | J31: Active – paid unconfirmed | K31: About 26,000 per Hoodline (5% of registered voters citywide and in 5 of 8 wards) | L31: 180 days from petition adoption (exact date unknown); target is a 2027 DC special election | N31: =IF(M31="","",M31-'Read Me'!$B$30) | O31: unknown (organizers declined to say for the first attempt) | P31: unknown | Q31: Volunteer shift signup via Mobilize on https://onefairwage.org/dc (no paid positions listed) | R31: unknown | S31: Saru Jayaraman, President, One Fair Wage | T31: One Fair Wage, 275 7th Ave, 15th Floor, New York, NY 10001 | U31: https://onefairwage.org/dc | V31: Missed the Nov 2026 ballot. The OFW site says collection is underway for a 2027 special election; Jayaraman said collection would start July 2026. No evidence of paid circulators (sign-up is volunteer shifts). DC non-resident circulators must register with BOE before circulating. | W31: https://onefairwage.org/dc | X31: https://hoodline.com/2026/07/d-c-wage-war-put-on-ice-after-25-ballot-bid-misses-mark/ | Y31: https://washingtonian.com/2026/07/17/advocates-of-25-minimum-wage-in-dc-blame-lawsuit-for-ballot-delay/ | Z31: https://51st.news/dc-ballot-initiatives-2026-election/ | AA31: Pass 2 (gap-fill) | AB31: 46319
A32: P031 | B32: District of Columbia | C32: Northeast | D32: Citywide | E32: Other proposed DC initiatives at BOE hearing stage (DC Equal Homeownership Act; Vermelle Paid Maternity Leave Act; DC Cash Payment Reparations Act; Human Environment 'Block Up Plan') | F32: Various; only hearing notices and advisory opinions are posted | G32: Initiative (DC citywide), pre-circulation | H32: unknown | I32: unknown | J32: Upcoming | K32: 5% of registered voters citywide and in 5 of 8 wards (about 24,000) | L32: 180 days after petition adoption (not yet adopted / unknown) | N32: =IF(M32="","",M32-'Read Me'!$B$30) | O32: unknown | P32: unknown | Q32: unknown | R32: unknown | S32: unknown | T32: DC BOE Voter Services (202) 727-2525, voterservices@dcboe.org | U32: https://dcboe.org/ballot-measures/current-measures | V32: These are listed on the BOE Current Measures page with no proposer or circulation dates shown. Approval for circulation is not confirmed. DC Referendum 009 (tipped wage timeline, Oct 2025) and Initiative 84 (Time Stability) also appear there; their current status was not verified. | W32: https://dcboe.org/ballot-measures/current-measures | X32: https://www.dcboe.org/getmedia/b8938d4f-b7c7-4912-8e9a-6287b1783db1/FINAL-Circulating-and-Filing-Initiative-Ref-Measure-Petitions-12152025.pdf | AA32: Pass 2 (gap-fill) | AB32: 46319
A33: P032 | B33: District of Columbia | C33: Northeast | D33: Citywide | E33: Initiative 88: Rent Control and Housing Eligibility Adjustment Amendment Act of 2026 (rent freeze) | F33: Two-year rent freeze on multifamily housing, plus extra 12-month freezes when DC-area CPI exceeds 5% | G33: Initiative (DC citywide) | H33: More Affordable D.C. (committee) | I33: unknown | J33: Upcoming | K33: About 24,000 valid (5% of registered voters citywide, incl. 5% in 5 of 8 wards) | L33: 180 days from final approval once litigation clears; earliest ballot is the expected spring 2027 special election | N33: =IF(M33="","",M33-'Read Me'!$B$30) | O33: unknown | P33: unknown | Q33: unknown | R33: unknown | S33: unknown | T33: unknown | U33: https://secure.actblue.com/donate/dcaffordability (committee donation page) | V33: Litigation blocked collection. A challenge led by the DC Building Industry Association coalition was denied as untimely on Sept 16, 2026; an appeal was filed Sept 18. Whether circulation has started is unknown. Opposition (DCBIA, NAR) is well funded, so a well-funded drive is plausible, but that is not confirmed. | W33: https://www.ballardspahr.com/insights/alerts-and-articles/2026/07/july-2026-dc-multifamily-update | X33: https://www.ballardspahr.com/insights/alerts-and-articles/2026/09/sept-23-2026-multifamily-client-alert | Y33: https://www.credaily.com/?p=222981 | Z33: https://www.nar.realtor/news/real-estate-news/nar-joins-challenge-to-d-c-rent-freeze-ballot-initiative; https://dcboe.org/ballot-measures/current-measures | AA33: Pass 2 (gap-fill) | AB33: 46319
A34: P033 | B34: District of Columbia | C34: Northeast | D34: Citywide | E34: Initiative 86: Prohibiting the Force-Feeding of Birds (foie gras ban) | F34: Ban sale of foie gras produced by force-feeding | G34: Initiative (DC citywide) | H34: Pro-Animal DC (campaign committee) | I34: unknown | J34: Completed/Expired | K34: 23,940 valid | L34: Qualified Aug 5, 2026; on Nov 3, 2026 ballot | M34: 46239 | N34: =IF(M34="","",M34-'Read Me'!$B$30) -> -80 | O34: 46,020 submitted; 31,726 valid; 198 circulators over 14 weeks | P34: unknown | Q34: unknown | R34: unknown | S34: unknown | T34: unknown | U34: unknown | V34: Collection is complete. Included as a reference point for what a DC drive takes (198 circulators, 14 weeks, record-setting signature count). | W34: https://www.popville.com/2026/08/force-fed-foie-gras-prohibition-dc-i86-qualifies-for-nov-ballot/ | AA34: Pass 2 (gap-fill) | AB34: 46319
A35: P034 | B35: Florida | C35: Southeast | D35: Statewide | E35: Florida Decides Healthcare - Medicaid expansion (2028) | F35: Constitutional amendment to expand Medicaid to adults 18-64 with incomes at or below 138% of the federal poverty level | G35: Statewide citizen initiative constitutional amendment | H35: Florida Decides Healthcare (Executive Director Mitch Emerson) | I35: unknown for 2028. For the 2026 drive, The Outreach Team posted paid 'Petitioner' jobs (posted April 8, 2025). | J35: Active – paid unconfirmed | K35: 880,062 was the 2026-cycle requirement (8% of voters). The exact 2028 figure is unknown. | L35: Feb 1, 2028 (standard Florida deadline for the 2028 ballot; not separately confirmed in sources) | M35: 46784 | N35: =IF(M35="","",M35-'Read Me'!$B$30) -> 465 | O35: Brevard County: 100 valid in total (7 valid 9/1-9/30/2026) as of 9/30/2026. Monroe County: 125 verified as of 1/30/2026. Statewide 2028 total unknown. The 2026 drive validated 75,855 of 90,250 submitted. | P35: 2026 drive (The Outreach Team, April 2025 posting): $19/hr for circulators, $21-25/hr for leadership, +$1/hr bilingual. The 2028 rate is unknown. | Q35: https://careers.arena.run/companies/the-outreach-team-2/jobs/48573140-petitioner-help-expand-medicaid-in-florida (2025 posting for the 2026 drive; current status unknown) | R35: unknown | S35: Mitch Emerson, Executive Director (per AP/CBS) | T35: unknown | U35: https://floridadecideshealthcare.org | V35: Relaunched signature collection for 2028 on Feb 1, 2026. The new model is mail-in petitions (prepaid return envelope) requested through the website, plus 100+ grassroots partners; that model points away from paid field circulation. Brevard's monthly valid count is small (7 in September 2026), which points to low field activity. The group says HB 1205 'dramatically increased petition costs.' It was lead plaintiff in Florida Decides Healthcare v. Byrd. On April 30, 2026, Judge Walker upheld the circulator registration requirement, the out-of-state and non-citizen circulator bans, felon restrictions, the $50,000-per-violation fine and the felony for filling in petition information. Ballot Access News reported the plaintiffs did not plan to appeal (BAN's May 1 post said the ruling would be appealed, so these conflict). The Florida DOS initiative database (constitutionalinitiatives.dos.fl.gov) was blocked by Cloudflare and could not be checked directly. | W35: https://www.beckerspayer.com/payer/medicaid/florida-medicaid-expansion-campaign-sets-sights-on-2028-ballot/ | X35: https://floridaphoenix.com/2026/04/30/federal-judge-upholds-floridas-citizen-initiative-restrictions/ | Y35: https://careers.arena.run/companies/the-outreach-team-2/jobs/48573140-petitioner-help-expand-medicaid-in-florida | Z35: https://jobs.arena.run/jobs/field-director-recx-ua8s9k-n6-fw-cq-p; https://www.cbsnews.com/amp/miami/news/campaign-delays-push-to-expand-medicaid-in-florida-until-2028-citing-new-state-law; https://jaxtoday.org/2026/02/02/constitutional-amendments-florida-failed/; https://www.votebrevard.gov/Voter-Data-and-Maps/Statistics-and-Data/Initiative-Petition-Totals; https://www.votemonroeflkeys.gov/Candidates-Petitions/Initiative-Petitions | AA35: Pass 1 + Pass 2 | AB35: 46319
A36: P035 | B36: Florida | C36: Southeast | D36: Statewide | E36: Defending Unborn Life (Initiative 25-06) | F36: Anti-abortion constitutional amendment (title only; full text not reviewed) | G36: Statewide citizen initiative constitutional amendment | H36: unknown (state volunteer petition form DSDE155A_999_2506 exists) | I36: unknown | J36: Active – paid unconfirmed | K36: unknown for 2028 | L36: Feb 1, 2028 (standard Florida deadline; not separately confirmed) | M36: 46784 | N36: =IF(M36="","",M36-'Read Me'!$B$30) -> 465 | O36: Brevard County: 5 valid as of 9/30/2026. Statewide total unknown. | P36: unknown | Q36: unknown | R36: unknown | S36: unknown | T36: unknown | U36: unknown | V36: Listed as an active initiative on the Brevard SOE totals page (9/30/2026). The volunteer form suggests volunteer collection. The very low count points to no meaningful paid drive. | W36: https://www.votebrevard.gov/Voter-Data-and-Maps/Statistics-and-Data/Initiative-Petition-Totals | X36: https://initiativepetitions.dos.fl.gov/InitiativeForms/Volunteer/DSDE155A_999_2506_EN.pdf | AA36: Pass 1 | AB36: 46319
A37: P036 | B37: Florida | C37: Southeast | D37: City of Fort Meade (Polk County) | E37: Fort Meade recall - Mayor Jaret Williams, Vice Mayor Petrina McCutchen, Commissioner Mathew Taylor | F37: Recall three city officials after approval of a 4.4-million-sq-ft Stonebridge hyperscale data center | G37: Municipal recall petition | H37: Fort Meade recall committee (chair Michael Bennett; Watchdogs of Fort Meade involved) | I37: unknown (appears volunteer) | J37: Active – paid unconfirmed | K37: First phase ~10% (about 246 minimum per organizer); second phase 15% of registered voters (~400) | L37: unknown | N37: =IF(M37="","",M37-'Read Me'!$B$30) | O37: More than 1,000 first-phase signatures submitted to City Hall (July 17, 2026) | P37: unknown | Q37: unknown | R37: unknown | S37: Michael Bennett (committee chair) | T37: unknown | U37: unknown | V37: Appears resident-led; no evidence of paid circulators. Status after the July 2026 SOE verification is unknown. Listed as a local petition opportunity, not a confirmed paid job. | W37: https://baynews9.com/fl/tampa/news/2026/07/17/fort-meade-recall-committee-submits-petitions-to-remove-city-leaders | X37: https://mynews13.com/fl/orlando/news/2026/07/17/fort-meade-recall-committee-submits-petitions-to-remove-city-leaders | Y37: https://www.tampabay28.com/news/region-polk/recall-effort-targets-three-fort-meade-city-leaders-after-data-center-approval | AA37: Pass 1 + Pass 2 | AB37: 46319
A38: P037 | B38: Florida | C38: Southeast | D38: City of Miami (Miami-Dade County) | E38: Stronger Miami charter amendment petition | F38: Change the City of Miami charter: expand the commission from 5 to 9 districts, move city elections to even years starting 2028, and set neighborhood-preserving, non-partisan redistricting rules | G38: Municipal charter amendment citizen petition | H38: Stronger Miami Coalition (One Grove Alliance, Florida Rising and other nonprofits) | I38: unknown | J38: Active – paid unconfirmed | K38: About 20,000 certified signatures | L38: unknown | N38: =IF(M38="","",M38-'Read Me'!$B$30) | O38: About 20,500 submitted; as of Feb 25, 2026, 13,416 reviewed, 7,203 certified, 6,213 uncertified, ~5,000 under review plus ~1,000 more turned in | P38: unknown | Q38: unknown | R38: unknown | S38: Teresa Guzman Pagan, Florida Rising (quoted director) | T38: unknown | U38: https://floridarising.org (coalition member) | V38: Latest verified status is Feb 2026. Whether it later qualified or is still collecting is unknown; the search budget ran out before this could be checked. The ~30% invalid rate suggests heavy field collection, but paid circulation is not confirmed. | W38: https://www.wlrn.org/government-politics/2026-02-26/stronger-miami-petition-ballot-miami | X38: https://www.wlrn.org/government-politics/2026-02-23/stronger-miami-government-petition-ballot-signatures | AA38: Pass 1 | AB38: 46319
A39: P038 | B39: Florida | C39: Southeast | D39: Statewide | E39: Floridians for Marijuana (2028 adult-use cannabis initiative) | F39: Constitutional amendment legalizing adult-use cannabis | G39: Statewide citizen initiative constitutional amendment | H39: Floridians for Marijuana political committee (chair Zack Whitson, treasurer Gloria Maggiolo) | I39: unknown | J39: Upcoming | K39: unknown for 2028 (8% of votes in the last presidential election; ~880,000 range per reporting) | L39: Feb 1, 2028 (standard Florida deadline; not separately confirmed) | M39: 46784 | N39: =IF(M39="","",M39-'Read Me'!$B$30) -> 465 | O39: unknown | P39: unknown | Q39: unknown | R39: unknown | S39: Zack Whitson (chair) | T39: unknown | U39: unknown | V39: Petition approved by the Division of Elections on Sept 30, 2026. No signature count, funding or circulation firm was found. A registered petition is not the same as active paid circulation. | W39: https://www.cannabisbusinesstimes.com/us-states/florida/news/15836634/florida-may-have-3-options-to-legalize-adultuse-cannabis-in-2028 | AA39: Pass 1 + Pass 2 | AB39: 46319
A40: P039 | B40: Florida | C40: Southeast | D40: Statewide | E40: Let Florida Vote IV (2028 cannabis initiative) | F40: Constitutional amendment legalizing adult-use cannabis | G40: Statewide citizen initiative constitutional amendment | H40: Political committee chaired by Zack Whitson (treasurer Gloria Maggiolo) | I40: unknown | J40: Upcoming | K40: unknown for 2028 | L40: Feb 1, 2028 (standard Florida deadline; not separately confirmed) | M40: 46784 | N40: =IF(M40="","",M40-'Read Me'!$B$30) -> 465 | O40: unknown | P40: unknown | Q40: unknown | R40: unknown | S40: Zack Whitson (chair) | T40: unknown | U40: unknown | V40: Pending with the Financial Impact Estimating Conference as of Sept 29, 2026, per Cannabis Business Times. The wording suggests it has already crossed the 25% review threshold, but that is not stated, so treat the count as unknown. | W40: https://www.cannabisbusinesstimes.com/us-states/florida/news/15836634/florida-may-have-3-options-to-legalize-adultuse-cannabis-in-2028 | AA40: Pass 1 + Pass 2 | AB40: 46319
...

Sheet Active Opportunities
A1: Ranked Opportunities — live and near-live projects
A2: Each project gets 0–5 points on the five ranking rules. Total is a formula. Scoring: Hiring = 5 with a live job link, 2 if a firm is named. Pay = 5 if a dollar rate is published. Urgency = 5 if deadline ≤45 days, 4 ≤90, 3 ≤180, 2 ≤400, 1 unknown. Scale = signatures required (5 ≥300k, 4 ≥70k, 3 statewide/≥20k, 2 local, 1 unknown). Evidence = 5 confirmed, 4 strong, 2 unconfirmed, 1 upcoming.
A4: Rank | B4: State | C4: Campaign / Petition | D4: Status | E4: Circulation Firm | F4: Circulator Pay | G4: Deadline | H4: Signatures Required | I4: Hiring Link | J4: Hiring | K4: Pay | L4: Urgency | M4: Scale | N4: Evidence | O4: TOTAL (0–25) | P4: Why it matters
A5: 1 | B5: Maine | C5: An Act to Amend the Cannabis Legalization Act and the Maine Medical Use of Cannabis Act | D5: Strong evidence active paid | E5: unknown. Out-of-state paid circulators were reported | F5: $1 per signature (one circulator, in a recording reported Jan 2026) | G5: June 8, 2027 filing deadline (for a 2027 election); Feb 2, 2026 was the 2026 cutoff | H5: 67,682 valid | I5: unknown | J5: 2 | K5: 5 | L5: 2 | M5: 3 | N5: 4 | O5: =SUM(J5:N5) -> 16 | P5: Approved for circulation Dec 8, 2025. In Jan 2026, Secretary Bellows testified that circulators were 'people for hire' shipped in from out of state. A Texas circulator said he was paid $1 per signature. The SOS page still lists it as current, with a June 8, 2027 deadline. Not verified whether signatures were filed for 2026 or whether paid collection continues in Oct 2026.
A6: 2 | B6: Florida | C6: Florida Decides Healthcare - Medicaid expansion (2028) | D6: Active – paid unconfirmed | E6: unknown for 2028. For the 2026 drive, The Outreach Team posted paid 'Petitioner' jobs (posted April 8, 2025). | F6: 2026 drive (The Outreach Team, April 2025 posting): $19/hr for circulators, $21-25/hr for leadership, +$1/hr bilingual. The 2028 rate is unknown. | G6: Feb 1, 2028 (standard Florida deadline for the 2028 ballot; not separately confirmed in sources) | H6: 880,062 was the 2026-cycle requirement (8% of voters). The exact 2028 figure is unknown. | I6: https://careers.arena.run/companies/the-outreach-team-2/jobs/48573140-petitioner-help-expand-medicaid-in-florida (2025 posting for the 2026 drive; current status unknown) | J6: 5 | K6: 5 | L6: 1 | M6: 3 | N6: 2 | O6: =SUM(J6:N6) -> 16 | P6: Relaunched signature collection for 2028 on Feb 1, 2026. The new model is mail-in petitions (prepaid return envelope) requested through the website, plus 100+ grassroots partners; that model points away from paid field circulation. Brevard's monthly valid count is small (7 in September 2026), which points to low field activity. The group says HB 1205 'dramatically increased petition costs.' It was lead plaintiff in Florida Decides Healthcare v. Byrd. On April 30, 2026, Judge Walker upheld the circulator registration requirement, the out-of-state and non-citizen circulator bans, felon restrictions, the $50,000-per-violation fine and the felony for filling in petition information. Ballot Access News reported the plaintiffs did not plan to appeal (BAN's May 1 post said the ruling would be appealed, so these conflict). The Florida DOS initiative database (constitutionalinitiatives.dos.fl.gov) was blocked by Cloudflare and could not be checked directly.
A7: 3 | B7: California | C7: Urban Signers LLC - Signature Collector (unnamed petition projects) | D7: Active – paid unconfirmed | E7: Urban Signers LLC | F7: $5 or $10 per signature depending on project; advertised $200-$1,000/day; paid weekly or bi-weekly | G7: unknown | H7: unknown | I7: https://urban-signers-llc.careerplug.com/jobs/3365854 | J7: 5 | K7: 5 | L7: 1 | M7: 1 | N7: 2 | O7: =SUM(J7:N7) -> 14 | P7: Paid job ad; page metadata updated 2026-10-16 (original post date unknown). Names no specific petition, and the only statewide CA petition circulating is the top-two repeal, so which projects are active is unverified.
A8: 4 | B8: Massachusetts | C8: SignatureDrive.com 'speculative' 2028 petitions (incl. 26-06 legislative employee bargaining and 26-12 end gas tax) | D8: Active – paid unconfirmed | E8: SignatureDrive.com (Harold Hubschman) is the filer and would be the firm | F8: unknown | G8: Nov 18, 2026 to local clerks; Dec 2, 2026 to Secretary of State | H8: 74,574 each | I8: unknown | J8: 2 | K8: 0 | L8: 5 | M8: 4 | N8: 2 | O8: =SUM(J8:N8) -> 13 | P8: The Globe names only 2 of the 10 topics; which certified numbers are Hubschman's beyond 26-06 and 26-12 is unverified. With no paying client as of Sept 22, 2026, these may not circulate at scale.
A9: 5 | B9: Massachusetts | C9: Other AG-certified 2028 petitions: 26-01, 26-05, 26-09, 26-10, 26-11, 26-14, 26-15, 26-16, 26-17, 26-18 | D9: Active – paid unconfirmed | E9: SignatureDrive.com (Hubschman's firm) would be the natural vendor, but it is not confirmed collecting on these | F9: unknown | G9: Nov 18, 2026 to local election officials; Dec 2, 2026 to Secretary of the Commonwealth | H9: 74,574 each (first round) | I9: unknown | J9: 2 | K9: 0 | L9: 5 | M9: 4 | N9: 2 | O9: =SUM(J9:N9) -> 13 | P9: A signature-firm owner filed these as products he can pitch to funders. 26-07 and 26-13 were filed but not certified. Any of the 10 could become a paid drive if a funder buys in before Nov 18. These are prime prospects for a petition-management pitch: the measures are certified but have no client yet.
A10: 6 | B10: Louisiana | C10: Recall of Gov. Jeff Landry (and AG Liz Murrill) | D10: Active – paid unconfirmed | E10: unknown | F10: unknown | G10: October 31 2026 (180 days from May 4 2026) | H10: 500,884 | I10: unknown | J10: 0 | K10: 0 | L10: 5 | M10: 5 | N10: 2 | O10: =SUM(J10:N10) -> 12 | P10: Petition began May 4 2026; deadline 7 days away. Appears volunteer-driven (fixed signing sites); no paid circulator evidence. Signature count not reported.
A11: 7 | B11: Massachusetts | C11: Initiative Petition 26-08: data center regulation (2028 ballot) | D11: Active – paid unconfirmed | E11: unknown. Boston.com reports Fleming is tied to JEF Associates, which provides certified signatures and ballot-initiative services; not confirmed as the vendor for this drive | F11: unknown | G11: Nov 18, 2026 to local election officials; Dec 2, 2026 to Secretary of the Commonwealth | H11: 74,574 (first round); about 12,500 more if the Legislature does not act | I11: unknown | J11: 2 | K11: 0 | L11: 5 | M11: 3 | N11: 2 | O11: =SUM(J11:N11) -> 12 | P11: Certified per Foley Hoag. Ballotpedia calls it the nation's second statewide data-center measure. There is no evidence of funding or paid circulation. Possible prospect: environmental or anti-data-center groups would be natural funders.
